Workbook

Sheet READ_ME
A1: RASMITRA | Commercial feasibility model
A3: Purpose | B3: FY22–FY24 bottom-up NPD diversification model. Illustrative assumptions; NOT verified consumer demand.
A4: Source 1 | B4: Case brief: The Growth Gambit, exhibits 1–6; fictional FY21 financials. Uploaded by team.
A5: Source 2 | B5: Team proposal: 6 products × 2 pack formats; category targets ₹135/₹75/₹60 Cr in FY24.
A6: Scope | B6: Revenue, pack/channel economics, financing, working capital, downside, quarterly concentration, target checks.
A7: Input rule | B7: BLUE numbers + pale-yellow background = editable assumptions; GREEN = links to another workbook tab; BLACK = calculated.
A8: Model logic | B8: Average PRODUCTIVE outlets × weekly unit sales × selling weeks × consumer sell-through = net packs.
A9: Revenue accounting | B9: MRP × (1 − blended channel margin) = company realisation (₹/pack). Trade spend is charged on company sales.
A10: Margin warning | B10: Channel partner margins and trade spend are distinct, and should not be added as percentages of the same base.
A11: Case limits | B11: Category market share is only a cross-check. Market size ≠ captive demand. No evidence to forecast 51% plant utilisation improvement.
A12: Period labels | B12: FY22–FY24 represent the case timeline, not current Indian market prices. Current quotes must be time-normalised.
A13: Scenario toggle | B13: Assumptions!C6 controls Base versus Downside; negative shock hits velocity, COGS, trade charges and DSO.
A14: Input caution | B14: All prices, pack COGS, velocity, outlet ramp, ROI and programme cash spend are planning assumptions unless labelled Case.
... A19: FGD evidence | B19: FGD participation does not establish population-wide price sensitivity, trial conversion, category demand or repurchase rates.
A21: Deck_TopDown tab (added for the submission): the top-down category model that produces the deck base case (18.5% FY24 new-product share, Rs 757.3 Cr revenue). Volumes on the deck come from that tab; margins, budget and working capital from the bottom-up tabs.
A22: Checks tab fix: FY24 target tests previously compared the wrong header column and showed N/A; they now read FY22-FY24 correctly.

Sheet Deck_TopDown
A1: DECK BASE CASE | Top-down category model (team category screen), the numbers used on pages 2-4 of the deck
A2: Blue cells are inputs. Change Scenario (B3) or Third category (B4) to see every scenario in the deck. This tab sets volumes; margins, budget and working capital come from the bottom-up tabs of this workbook.
A3: Scenario | B3: Base
A4: Third category from FY23 | B4: None
A6: Category | B6: Market FY21 (Rs Cr) | C6: 3-yr CAGR | D6: Organised share | E6: Our share by year 3 | F6: Selling months | G6: Sales in Mar-Jul | H6: Contribution margin | I6: Source
A7: Spices | B7: 78000 | C7: 0.11 | D7: 0.42 | E7: 0.03 | F7: 12 | G7: =5/12 -> 0.41666667 | H7: 0.199 | I7: Exhibit 5; team estimates; Excel contribution
A8: Premixes | B8: 6400 | C8: 0.14 | D8: 0.55 | E8: 0.1 | F8: 5 | G8: 0.1 | H8: 0.256 | I8: Exhibit 5; team estimates; Excel contribution
A9: Pickles | B9: 12500 | C9: 0.13 | D9: 0.38 | E9: 0.05 | F9: 12 | G9: =5/12 -> 0.41666667 | H9: 0.224 | I9: Exhibit 5; team estimates; Excel contribution (condiments)
A10: RTC mixes | B10: 9800 | C10: 0.17 | D10: 0.61 | E10: 0.04 | F10: 12 | G10: =5/12 -> 0.41666667 | H10: 0.22 | I10: Exhibit 5; team estimates; contribution team estimate
A12: Net realisation (Rs 147 / Rs 195) | B12: =147/195 -> 0.75384615 | C12: Exhibit 2
A13: Core business FY21 (Rs Cr) | B13: 536.48 | C13: Exhibit 1: Rs 560 Cr less 4.2% new products
A14: Core growth a year | B14: 0.048 | C14: Exhibit 1: FY18-21 CAGR
A15: Today's new products FY21 (Rs Cr) | B15: 23.52 | C15: Exhibit 1: 4.2% of Rs 560 Cr
A16: Today's new products growth | B16: 0.1 | C16: Team estimate
A17: Retail outlets reached | B17: 450000 | C17: Exhibit 1
A18: Share of outlets stocking each new category | B18: 0.5 | C18: Team estimate (velocity check only)
A20: Scenario | B20: Reach FY22 | C20: Reach FY23 | D20: Reach FY24 | E20: Share multiplier | F20: Premix ramp FY22 | G20: FY23 | H20: FY24 | I20: Spices ramp FY22 | J20: FY23 | K20: FY24 | L20: Third ramp FY22 | M20: FY23 | N20: FY24
A21: Base | B21: 0.08 | C21: 0.08 | D21: 0.08 | E21: 1 | F21: 0.3 | G21: 0.75 | H21: 1 | I21: 0.05 | J21: 0.6 | K21: 0.95 | L21: 0 | M21: 0.15 | N21: 0.75
A22: Stretch | B22: 0.08 | C22: 0.09 | D22: 0.1 | E22: 1.5 | F22: 0.3 | G22: 0.75 | H22: 1 | I22: 0.05 | J22: 0.6 | K22: 0.95 | L22: 0 | M22: 0.15 | N22: 0.75
A23: Downside | B23: 0.08 | C23: 0.08 | D23: 0.08 | E23: 0.6 | F23: 0 | G23: 0.3 | H23: 0.75 | I23: 0 | J23: 0.25 | K23: 0.75 | L23: 0 | M23: 0 | N23: 0.3
A24: Selected | B24: =INDEX(B21:B23,MATCH($B$3,$A$21:$A$23,0)) -> 0.08 | C24: =INDEX(C21:C23,MATCH($B$3,$A$21:$A$23,0)) -> 0.08 | D24: =INDEX(D21:D23,MATCH($B$3,$A$21:$A$23,0)) -> 0.08 | E24: =INDEX(E21:E23,MATCH($B$3,$A$21:$A$23,0)) -> 1 | F24: =INDEX(F21:F23,MATCH($B$3,$A$21:$A$23,0)) -> 0.3 | G24: =INDEX(G21:G23,MATCH($B$3,$A$21:$A$23,0)) -> 0.75 | H24: =INDEX(H21:H23,MATCH($B$3,$A$21:$A$23,0)) -> 1 | I24: =INDEX(I21:I23,MATCH($B$3,$A$21:$A$23,0)) -> 0.05 | ... N24: =INDEX(N21:N23,MATCH($B$3,$A$21:$A$23,0)) -> 0.75
A27: Revenue (Rs Cr, net realisation) | B27: FY21 | C27: FY22 | D27: FY23 | E27: FY24 | F27: FY25E | G27: FY26E
A28: Core business | B28: =B13 -> 536.48 | C28: =B28*(1+$B$14) -> 562.23104 | D28: =C28*(1+$B$14) -> 589.21813 | E28: =D28*(1+$B$14) -> 617.5006
A29: Today's new products | B29: =B15 -> 23.52 | C29: =B29*(1+$B$16) -> 25.872 | D29: =C29*(1+$B$16) -> 28.4592 | E29: =D29*(1+$B$16) -> 31.30512
A30: Premixes | B30: 0 | C30: =$B$8*(1+$C$8)^1*$D$8*B$24*$B$12*$E$8*$E$24*F$24 -> 7.2600812 | D30: =$B$8*(1+$C$8)^2*$D$8*C$24*$B$12*$E$8*$E$24*G$24 -> 20.691232 | E30: =$B$8*(1+$C$8)^3*$D$8*D$24*$B$12*$E$8*$E$24*H$24 -> 31.450672 | F30: =E30*(1+$C$8) -> 35.853766 | G30: =F30*(1+$C$8) -> 40.873293
A31: Spices | B31: 0 | C31: =$B$7*(1+$C$7)^1*$D$7*B$24*$B$12*$E$7*$E$24*I$24 -> 3.2895072 | D31: =$B$7*(1+$C$7)^2*$D$7*C$24*$B$12*$E$7*$E$24*J$24 -> 43.816236 | E31: =$B$7*(1+$C$7)^3*$D$7*D$24*$B$12*$E$7*$E$24*K$24 -> 77.007035 | F31: =E31/0.95*(1+$C$7) -> 89.97664 | G31: =F31*(1+$C$7) -> 99.874071
A32: Third category (if chosen) | B32: 0 | C32: =IF($B$4="Pickles",$B$9*(1+$C$9)^1*$D$9*B$24*$B$12*$E$9*$E$24*L$24,IF($B$4="RTC mixes",$B$10*(1+$C$10)^1*$D$10*B$24*$B$12*$E$10*$E$24*L$24,0)) -> 0 | D32: =IF($B$4="Pickles",$B$9*(1+$C$9)^2*$D$9*C$24*$B$12*$E$9*$E$24*M$24,IF($B$4="RTC mixes",$B$10*(1+$C$10)^2*$D$10*C$24*$B$12*$E$10*$E$24*M$24,0)) -> 0 | E32: =IF($B$4="Pickles",$B$9*(1+$C$9)^3*$D$9*D$24*$B$12*$E$9*$E$24*N$24,IF($B$4="RTC mixes",$B$10*(1+$C$10)^3*$D$10*D$24*$B$12*$E$10*$E$24*N$24,0)) -> 0 | F32: =E32*(1+IF($B$4="Pickles",$C$9,IF($B$4="RTC mixes",$C$10,0))) -> 0 | G32: =F32*(1+IF($B$4="Pickles",$C$9,IF($B$4="RTC mixes",$C$10,0))) -> 0
A33: New-category revenue | B33: =SUM(B30:B32) -> 0 | C33: =SUM(C30:C32) -> 10.549588 | D33: =SUM(D30:D32) -> 64.507467 | E33: =SUM(E30:E32) -> 108.45771 | F33: =SUM(F30:F32) -> 125.83041 | G33: =SUM(G30:G32) -> 140.74736
A34: New-product revenue | B34: =B29+B33 -> 23.52 | C34: =C29+C33 -> 36.421588 | D34: =D29+D33 -> 92.966667 | E34: =E29+E33 -> 139.76283
A35: Company revenue | B35: 560 | C35: =C28+C34 -> 598.65263 | D35: =D28+D34 -> 682.1848 | E35: =E28+E34 -> 757.26343
A36: New-product share of revenue | B36: =B34/B35 -> 0.042 | C36: =C34/C35 -> 0.060839269 | D36: =D34/D35 -> 0.13627784 | E36: =E34/E35 -> 0.18456302
A38: FY24 new-product revenue needed for 30% | E38: =0.3/0.7*E28 -> 264.64311
A39: FY24 gap to 30% (positive = short) | E39: =E38-E34 -> 124.88029
A40: FY24 sales earned Mar-Jul | E40: =((E28+E29)*0.58+E30*G8+E31*G7+E32*IF($B$4="Pickles",G9,IF($B$4="RTC mixes",G10,0)))/E35 -> 0.54345507
A41: Company revenue CAGR FY21-24 | E41: =(E35/560)^(1/3)-1 -> 0.10582478
A43: Sense checks, FY24 | B43: Premixes | C43: Spices
A44: Share of national market (MRP basis) | B44: =E30/$B$12/($B$8*(1+$C$8)^3) -> 0.0044 | C44: =E31/$B$12/($B$7*(1+$C$7)^3) -> 0.0009576
A45: Sales per stocking outlet a month at MRP (Rs) | B45: =E30/$B$12*10^7/($B$17*$B$18)/$F$8 -> 370.84692 | C45: =E31/$B$12*10^7/($B$17*$B$18)/$F$7 -> 378.34144
A46: FY24 revenue from one point of our share (Rs Cr, base reach 8%) | B46: =$B$8*(1+$C$8)^3*$D$8*0.08*$B$12*0.01 -> 3.1450672 | C46: =$B$7*(1+$C$7)^3*$D$7*0.08*$B$12*0.01 -> 27.020012
A48: Incremental P&L and cash (Rs Cr) | C48: FY22 | D48: FY23 | E48: FY24 | F48: FY25E | G48: FY26E
...

Sheet Dashboard
A1: RASMITRA | three-year growth feasibility dashboard
A3: CASE TARGET: FY24 ₹900Cr topline and ≥30% fresh-product revenue | illustrative editable model
A5: DECISION KPIs — formula-driven
A6: Key performance indicator | B6: FY22 | C6: FY23 | D6: FY24
A7: Total revenue ₹Cr | B7: =Portfolio!C11 -> 612.83354 | C7: =Portfolio!D11 -> 773.63535 | D7: =Portfolio!E11 -> 972.03308
A8: Fresh NPD revenue ₹Cr | B8: =Portfolio!C10 -> 32.833539 | C8: =Portfolio!D10 -> 168.63535 | D8: =Portfolio!E10 -> 342.03308
A9: New share of company sales | B9: =Portfolio!C12 -> 0.053576602 | C9: =Portfolio!D12 -> 0.21797782 | D9: =Portfolio!E12 -> 0.35187391
A10: Spices revenue ₹Cr | B10: =Portfolio!C7 -> 17.711862 | C10: =Portfolio!D7 -> 90.929627 | D10: =Portfolio!E7 -> 184.48265
A11: Winter premixes revenue ₹Cr | B11: =Portfolio!C8 -> 7.1380447 | C11: =Portfolio!D8 -> 36.668846 | D11: =Portfolio!E8 -> 74.395013
A12: Condiments revenue ₹Cr | B12: =Portfolio!C9 -> 7.9836316 | C12: =Portfolio!D9 -> 41.036876 | D12: =Portfolio!E9 -> 83.155415
A13: New-product contribution ₹Cr | B13: =P_and_L!B12 -> 7.1485783 | C13: =P_and_L!C12 -> 36.720708 | D13: =P_and_L!D12 -> 74.469354
A14: New-product EBITDA ₹Cr | B14: =P_and_L!B17 -> -4.8514217 | C14: =P_and_L!C17 -> 18.720708 | D14: =P_and_L!D17 -> 57.469354
A15: Project FCF ₹Cr | B15: =Cash_Flow!B11 -> -30.958459 | C15: =Cash_Flow!C11 -> -0.99356924 | D15: =Cash_Flow!D11 -> 48.340246
A16: Cumulative FCF ₹Cr | B16: =Cash_Flow!B12 -> -30.958459 | C16: =Cash_Flow!C12 -> -31.952029 | D16: =Cash_Flow!D12 -> 16.388217
A17: Net working capital ₹Cr | B17: =Working_Capital!B13 -> 2.1070377 | C17: =Working_Capital!C13 -> 10.821315 | D17: =Working_Capital!D13 -> 21.950424
A18: Budget committed cumulatively ₹Cr | B18: =Cash_Flow!B15 -> 18 | C18: =Cash_Flow!C15 -> 47 | D18: =Cash_Flow!D15 -> 75
A19: Programme budget headroom ₹Cr | B19: =Cash_Flow!B17 -> 57 | C19: =Cash_Flow!C17 -> 28 | D19: =Cash_Flow!D17 -> 0
A22: FY24 board-goal attainment
A23: Company revenue (model) | B23: =Portfolio!E11 -> 972.03308
A24: Company revenue goal | B24: =Assumptions!F11 -> 900
A25: Revenue gap ₹ Cr | B25: =B23-B24 -> 72.033077
A26: Fresh product share (model) | B26: =Portfolio!E12 -> 0.35187391
A27: NPD mix target | B27: =Assumptions!F12 -> 0.3
A28: NPD mix gap (percentage points) | B28: =B26-B27 -> 0.051873907
A29: Category demand vs target (₹Cr) | B29: =Portfolio!E10-SUM(Assumptions!D18:D20) -> 72.033077
A30: FY24 cumulative project cash flow | B30: =Cash_Flow!D12 -> 16.388217
A33: SCENARIO | B33: =Assumptions!C6 -> Base
A35: Budget / cash notes
A36: Budget commitment ≠ P&L expense; working-capital draw is based on actual calculated NWC, not on the reserved line.
A37: Model limitations
A38: FY24 baseline, channel velocities, pricing and gross profits are planning inputs. Plant utilisation and core EBITDA cannot be reliably projected.
A40: FY24 distributor net economic profit (₹Cr) | B40: =Distributor_Econ!J19 -> 6.8383464
A41: Annual net profit per participating distributor (₹) | B41: =Distributor_Econ!K19 -> 175342.21
A42: GT channel partner economic check | B42: =IF(Distributor_Econ!J19>0,"POSITIVE","LOSS") -> POSITIVE

Sheet Assumptions
A1: MASTER ASSUMPTIONS | all editable inputs
A3: Sources: Exhibit = case data; Team = submitted strategy; Illustrative = editable, needs pilot/quotes.
A5: Model control | J5: GT economic detail | K5: Value | L5: Source | M5: Explanation
B6: Selected scenario | C6: Base | E6: FY21 revenue (₹Cr) | F6: 560 | G6: Exhibit 1 | J6: Retailer margin / consumer MRP | K6: 0.18 | L6: Exhibit 2 Products A/B | M6: Illustrative proxy for new foods
B7: Downside unit velocity shock | C7: 0.3 | E7: FY21 new products share | F7: 0.042 | G7: Exhibit 1 | J7: Distributor margin / retailer buy price | K7: 0.08 | L7: Exhibit 2 Products A/B | M7: Do not combine as 26% of consumer MRP
B8: Downside COGS surcharge / sales | C8: 0.03 | E8: FY21 gross margin | F8: 0.36 | G8: Exhibit 1 | J8: Distributor handling cost / trial pack ₹ | K8: 0.4 | L8: Illustrative | M8: Returns, picking, van delivery
B9: Downside extra trade spend | C9: 0.02 | E9: FY21 EBITDA margin | F9: 0.105 | G9: Exhibit 1 | J9: Distributor handling cost / large pack ₹ | K9: 2.2 | L9: Illustrative | M9: Returns, picking, van delivery
B10: Downside extra DSO (days) | C10: 15 | E10: Programme funding ceiling (₹Cr) | F10: 75 | G10: Board mandate | J10: Stockholding days at distributor | K10: 18 | L10: Illustrative | M10: Supply partner interviews required
B11: Annual retail MRP increase | C11: 0 | E11: FY24 sales ambition (₹Cr) | F11: 900 | G11: Board mandate | J11: Distributor cost of funds pa | K11: 0.14 | L11: Illustrative | M11: Interest and inventory finance
B12: Annual unit COGS inflation | C12: 0 | E12: FY24 new-product share target | F12: 0.3 | G12: Board mandate | J12: Distributors participating by FY24 | K12: 390 | L12: Exhibit 1, assumption | M12: Case has 390 distributors; all-participating is unvalidated
B13: Consumer sell-through proxy | C13: 0.95 | J13: Distributor funding cycle days | K13: 21 | L13: Illustrative | M13: Not automatically the same as company DSO
A15: Core business + category planning targets (₹ Cr)
A16: Revenue assumption | B16: FY22 | C16: FY23 | D16: FY24 | E16: Source | F16: Important caveat
A17: Legacy portfolio | B17: 580 | C17: 605 | D17: 630 | E17: Team scenario | F17: Legacy includes FY21 portfolio; these are NOT validated forecasts
A18: Spices target | B18: 10 | C18: 70 | D18: 135 | E18: Team scenario | F18: Comparator only, not forced in formula
A19: Winter premix target | B19: 8 | C19: 40 | D19: 75 | E19: Team scenario | F19: Comparator only, not forced in formula
A20: Condiments target | B20: 2 | C20: 25 | D20: 60 | E20: Team scenario | F20: Comparator only, not forced in formula
A22: SKU/format assumptions — all price and unit COGS inputs are hypothetical
A23: Code | B23: Category | C23: Proposed SKU | D23: Pack format | E23: MRP FY22 ₹ | F23: Unit COGS FY22 ₹ | G23: Weeks/year | H23: Source | I23: Pricing caution
A24: SAB_T | B24: Spices | C24: Everyday Sabzi Masala | D24: 8g trial | E24: 10 | F24: 5.25 | G24: 52 | H24: Illustrative | I24: Trial pack may be uneconomic online
A25: SAB_L | B25: Spices | C25: Everyday Sabzi Masala | D25: 50g pouch | E25: 49 | F25: 23 | G25: 52 | H25: Team + illustrative | I25: ₹49 MRP hypothetical
A26: GAR_T | B26: Spices | C26: Garam Masala | D26: 5g trial | E26: 10 | F26: 5.35 | G26: 52 | H26: Illustrative | I26: Trial pack may be uneconomic online
A27: GAR_L | B27: Spices | C27: Garam Masala | D27: 50g pouch | E27: 49 | F27: 23.5 | G27: 52 | H27: Team + illustrative | I27: ₹49 MRP hypothetical
A28: GIN_T | B28: Premixes | C28: Ginger-Lemon Hot Drink | D28: 15g single sachet | E28: 10 | F28: 4.35 | G28: 26 | H28: Team + illustrative | I28: Check against ginger tea competitors
A29: GIN_L | B29: Premixes | C29: Ginger-Lemon Hot Drink | D29: 10-sachet pack | E29: 99 | F29: 44 | G29: 26 | H29: Team + illustrative | I29: ₹99 may be premium vs incumbent
A30: BAD_T | B30: Premixes | C30: Badam-Elaichi Milk Mix | D30: 15g single sachet | E30: 10 | F30: 4.5 | G30: 26 | H30: Team + illustrative | I30: Customer must additionally buy milk
A31: BAD_L | B31: Premixes | C31: Badam-Elaichi Milk Mix | D31: 150g pouch | E31: 99 | F31: 45.5 | G31: 26 | H31: Team + illustrative | I31: Customer must additionally buy milk
A32: CHU_T | B32: Condiments | C32: Tamarind-Date Chutney | D32: 20g sachet | E32: 10 | F32: 4.8 | G32: 52 | H32: Team + illustrative | I32: Packaging/storage stability to test
A33: CHU_L | B33: Condiments | C33: Tamarind-Date Chutney | D33: 200g pack | E33: 99 | F33: 47 | G33: 52 | H33: Team + illustrative | I33: Shelf-life/cost to test
A34: PIC_T | B34: Condiments | C34: Lime Pickle | D34: 20g sachet | E34: 10 | F34: 4.7 | G34: 52 | H34: Team + illustrative | I34: Sampling and local taste to test
A35: PIC_L | B35: Condiments | C35: Lime Pickle | D35: 200g pack | E35: 99 | F35: 46.5 | G35: 52 | H35: Team + illustrative | I35: Shelf-life/cost to test
A38: Channel economics — case partner margins / trade spend and credit days
A39: Channel | B39: Partner margin / MRP | C39: Trade spend / net revenue | D39: DSO days | E39: Freight ₹/pack | F39: Inventory days | G39: DPO days | H39: Source
A40: GT | B40: 0.25 | C40: 0.065 | D40: 21 | E40: 1 | F40: 28 | G40: 30 | H40: Exhibit 3 margins, trade, credit; other = assumption
A41: Modern | B41: 0.28 | C41: 0.14 | D41: 45 | E41: 1.7 | F41: 35 | G41: 30 | H41: Exhibit 3 margins, trade, credit; other = assumption
A42: QCom | B42: 0.38 | C42: 0.24 | D42: 32 | E42: 2 | F42: 21 | G42: 30 | H42: Exhibit 3 margins, trade, credit; other = assumption
A45: Programme budget: 3-year allocation, ₹ Cr (source: team scenario, EDITABLE)
A46: Budget use | B46: FY22 | C46: FY23 | D46: FY24 | E46: 3-year total | F46: Accounting treatment
A47: Launch A&P, sampling | B47: 8 | C47: 14 | D47: 13 | E47: =SUM(B47:D47) -> 35 | F47: Operating programme expense
A48: Incremental working capital envelope | B48: 4 | C48: 7 | D48: 7 | E48: =SUM(B48:D48) -> 18 | F48: Funding reserve; not operating expense
...

Sheet SKU_Channel_Model
A1: BOTTOM-UP SALES ENGINE | 12 packs × 3 channels × 3 years
A3: Blue demand assumptions are on Assumptions tab; values here are linked. Sales use consumer offtake proxy, not pipeline stuffing.
A5: FY | B5: SKU code | C5: Category | D5: Channel | E5: MRP ₹ | F5: COGS/pack ₹ | G5: Selling weeks | H5: Avg productive outlets | I5: Packs/outlet/week | J5: Sell-through | K5: Partner margin | L5: Trade spend | M5: Freight/pack ₹ | N5: Gross shipped packs | O5: Net sold packs | P5: Company ₹/pack | Q5: Net revenue ₹Cr | R5: COGS ₹Cr | S5: Trade ₹Cr | T5: Freight ₹Cr | U5: Contribution ₹Cr | V5: Contrib. % | W5: Data source | X5: SKU name / pack
A6: =Assumptions!A58 -> FY22 | B6: =Assumptions!B58 -> SAB_T | C6: =Assumptions!B24 -> Spices | D6: =Assumptions!C58 -> GT | E6: =Assumptions!E24*(1+Assumptions!$C$11)^0 -> 10 | F6: =Assumptions!F24*(1+Assumptions!$C$12)^0 -> 5.25 | G6: =Assumptions!G24 -> 52 | H6: =Assumptions!D58 -> 10400 | I6: =Assumptions!E58 -> 2.58 | J6: =Assumptions!$C$13 -> 0.95 | K6: =Assumptions!B40 -> 0.25 | L6: =Assumptions!C40+IF(Assumptions!$C$6="Downside",Assumptions!$C$9,0) -> 0.065 | M6: =Assumptions!E40 -> 1 | N6: =H6*I6*G6*IF(Assumptions!$C$6="Downside",1-Assumptions!$C$7,1) -> 1395264 | O6: =N6*J6 -> 1325500.8 | P6: =E6*(1-K6) -> 7.5 | Q6: =O6*P6/10000000 -> 0.9941256 | R6: =O6*F6/10000000+IF(Assumptions!$C$6="Downside",Q6*Assumptions!$C$8,0) -> 0.69588792 | S6: =Q6*L6 -> 0.064618164 | T6: =O6*M6/10000000 -> 0.13255008 | U6: =Q6-SUM(R6:T6) -> 0.10106944 | V6: =IFERROR(U6/Q6,0) -> 0.10166667 | W6: =Assumptions!F58 -> Illustrative (replace with pilot) | X6: =Assumptions!C24&" | "&Assumptions!D24 -> Everyday Sabzi Masala | 8g trial
A7: =Assumptions!A59 -> FY22 | B7: =Assumptions!B59 -> SAB_T | C7: =Assumptions!B24 -> Spices | D7: =Assumptions!C59 -> Modern | E7: =Assumptions!E24*(1+Assumptions!$C$11)^0 -> 10 | F7: =Assumptions!F24*(1+Assumptions!$C$12)^0 -> 5.25 | G7: =Assumptions!G24 -> 52 | H7: =Assumptions!D59 -> 364 | I7: =Assumptions!E59 -> 10.32 | J7: =Assumptions!$C$13 -> 0.95 | K7: =Assumptions!B41 -> 0.28 | L7: =Assumptions!C41+IF(Assumptions!$C$6="Downside",Assumptions!$C$9,0) -> 0.14 | M7: =Assumptions!E41 -> 1.7 | N7: =H7*I7*G7*IF(Assumptions!$C$6="Downside",1-Assumptions!$C$7,1) -> 195336.96 | O7: =N7*J7 -> 185570.11 | P7: =E7*(1-K7) -> 7.2 | Q7: =O7*P7/10000000 -> 0.13361048 | R7: =O7*F7/10000000+IF(Assumptions!$C$6="Downside",Q7*Assumptions!$C$8,0) -> 0.097424309 | S7: =Q7*L7 -> 0.018705467 | T7: =O7*M7/10000000 -> 0.031546919 | U7: =Q7-SUM(R7:T7) -> -0.014066214 | V7: =IFERROR(U7/Q7,0) -> -0.10527778 | W7: =Assumptions!F59 -> Illustrative (replace with pilot) | X7: =Assumptions!C24&" | "&Assumptions!D24 -> Everyday Sabzi Masala | 8g trial
A8: =Assumptions!A60 -> FY22 | B8: =Assumptions!B60 -> SAB_T | C8: =Assumptions!B24 -> Spices | D8: =Assumptions!C60 -> QCom | E8: =Assumptions!E24*(1+Assumptions!$C$11)^0 -> 10 | F8: =Assumptions!F24*(1+Assumptions!$C$12)^0 -> 5.25 | G8: =Assumptions!G24 -> 52 | H8: =Assumptions!D60 -> 146 | I8: =Assumptions!E60 -> 30.96 | J8: =Assumptions!$C$13 -> 0.95 | K8: =Assumptions!B42 -> 0.38 | L8: =Assumptions!C42+IF(Assumptions!$C$6="Downside",Assumptions!$C$9,0) -> 0.24 | M8: =Assumptions!E42 -> 2 | N8: =H8*I8*G8*IF(Assumptions!$C$6="Downside",1-Assumptions!$C$7,1) -> 235048.32 | O8: =N8*J8 -> 223295.9 | P8: =E8*(1-K8) -> 6.2 | Q8: =O8*P8/10000000 -> 0.13844346 | R8: =O8*F8/10000000+IF(Assumptions!$C$6="Downside",Q8*Assumptions!$C$8,0) -> 0.11723035 | S8: =Q8*L8 -> 0.033226431 | T8: =O8*M8/10000000 -> 0.044659181 | U8: =Q8-SUM(R8:T8) -> -0.0566725 | V8: =IFERROR(U8/Q8,0) -> -0.40935484 | W8: =Assumptions!F60 -> Illustrative (replace with pilot) | X8: =Assumptions!C24&" | "&Assumptions!D24 -> Everyday Sabzi Masala | 8g trial
A9: =Assumptions!A61 -> FY22 | B9: =Assumptions!B61 -> SAB_L | C9: =Assumptions!B25 -> Spices | D9: =Assumptions!C61 -> GT | E9: =Assumptions!E25*(1+Assumptions!$C$11)^0 -> 49 | F9: =Assumptions!F25*(1+Assumptions!$C$12)^0 -> 23 | G9: =Assumptions!G25 -> 52 | H9: =Assumptions!D61 -> 12000 | I9: =Assumptions!E61 -> 3.12 | J9: =Assumptions!$C$13 -> 0.95 | K9: =Assumptions!B40 -> 0.25 | L9: =Assumptions!C40+IF(Assumptions!$C$6="Downside",Assumptions!$C$9,0) -> 0.065 | M9: =Assumptions!E40 -> 1 | N9: =H9*I9*G9*IF(Assumptions!$C$6="Downside",1-Assumptions!$C$7,1) -> 1946880 | O9: =N9*J9 -> 1849536 | P9: =E9*(1-K9) -> 36.75 | Q9: =O9*P9/10000000 -> 6.7970448 | R9: =O9*F9/10000000+IF(Assumptions!$C$6="Downside",Q9*Assumptions!$C$8,0) -> 4.2539328 | S9: =Q9*L9 -> 0.44180791 | T9: =O9*M9/10000000 -> 0.1849536 | U9: =Q9-SUM(R9:T9) -> 1.9163505 | V9: =IFERROR(U9/Q9,0) -> 0.28193878 | W9: =Assumptions!F61 -> Illustrative (replace with pilot) | X9: =Assumptions!C25&" | "&Assumptions!D25 -> Everyday Sabzi Masala | 50g pouch
A10: =Assumptions!A62 -> FY22 | B10: =Assumptions!B62 -> SAB_L | C10: =Assumptions!B25 -> Spices | D10: =Assumptions!C62 -> Modern | E10: =Assumptions!E25*(1+Assumptions!$C$11)^0 -> 49 | F10: =Assumptions!F25*(1+Assumptions!$C$12)^0 -> 23 | G10: =Assumptions!G25 -> 52 | H10: =Assumptions!D62 -> 420 | I10: =Assumptions!E62 -> 12.48 | J10: =Assumptions!$C$13 -> 0.95 | K10: =Assumptions!B41 -> 0.28 | L10: =Assumptions!C41+IF(Assumptions!$C$6="Downside",Assumptions!$C$9,0) -> 0.14 | M10: =Assumptions!E41 -> 1.7 | N10: =H10*I10*G10*IF(Assumptions!$C$6="Downside",1-Assumptions!$C$7,1) -> 272563.2 | O10: =N10*J10 -> 258935.04 | P10: =E10*(1-K10) -> 35.28 | Q10: =O10*P10/10000000 -> 0.91352282 | R10: =O10*F10/10000000+IF(Assumptions!$C$6="Downside",Q10*Assumptions!$C$8,0) -> 0.59555059 | S10: =Q10*L10 -> 0.12789319 | T10: =O10*M10/10000000 -> 0.044018957 | U10: =Q10-SUM(R10:T10) -> 0.14606008 | V10: =IFERROR(U10/Q10,0) -> 0.15988662 | W10: =Assumptions!F62 -> Illustrative (replace with pilot) | X10: =Assumptions!C25&" | "&Assumptions!D25 -> Everyday Sabzi Masala | 50g pouch
A11: =Assumptions!A63 -> FY22 | B11: =Assumptions!B63 -> SAB_L | C11: =Assumptions!B25 -> Spices | D11: =Assumptions!C63 -> QCom | E11: =Assumptions!E25*(1+Assumptions!$C$11)^0 -> 49 | F11: =Assumptions!F25*(1+Assumptions!$C$12)^0 -> 23 | G11: =Assumptions!G25 -> 52 | H11: =Assumptions!D63 -> 168 | I11: =Assumptions!E63 -> 37.44 | J11: =Assumptions!$C$13 -> 0.95 | K11: =Assumptions!B42 -> 0.38 | L11: =Assumptions!C42+IF(Assumptions!$C$6="Downside",Assumptions!$C$9,0) -> 0.24 | M11: =Assumptions!E42 -> 2 | N11: =H11*I11*G11*IF(Assumptions!$C$6="Downside",1-Assumptions!$C$7,1) -> 327075.84 | O11: =N11*J11 -> 310722.05 | P11: =E11*(1-K11) -> 30.38 | Q11: =O11*P11/10000000 -> 0.94397358 | R11: =O11*F11/10000000+IF(Assumptions!$C$6="Downside",Q11*Assumptions!$C$8,0) -> 0.71466071 | S11: =Q11*L11 -> 0.22655366 | T11: =O11*M11/10000000 -> 0.06214441 | U11: =Q11-SUM(R11:T11) -> -0.059385198 | V11: =IFERROR(U11/Q11,0) -> -0.062909809 | W11: =Assumptions!F63 -> Illustrative (replace with pilot) | X11: =Assumptions!C25&" | "&Assumptions!D25 -> Everyday Sabzi Masala | 50g pouch
A12: =Assumptions!A64 -> FY22 | B12: =Assumptions!B64 -> GAR_T | C12: =Assumptions!B26 -> Spices | D12: =Assumptions!C64 -> GT | E12: =Assumptions!E26*(1+Assumptions!$C$11)^0 -> 10 | F12: =Assumptions!F26*(1+Assumptions!$C$12)^0 -> 5.35 | G12: =Assumptions!G26 -> 52 | H12: =Assumptions!D64 -> 9120 | I12: =Assumptions!E64 -> 2.22 | J12: =Assumptions!$C$13 -> 0.95 | K12: =Assumptions!B40 -> 0.25 | L12: =Assumptions!C40+IF(Assumptions!$C$6="Downside",Assumptions!$C$9,0) -> 0.065 | M12: =Assumptions!E40 -> 1 | N12: =H12*I12*G12*IF(Assumptions!$C$6="Downside",1-Assumptions!$C$7,1) -> 1052812.8 | O12: =N12*J12 -> 1000172.2 | P12: =E12*(1-K12) -> 7.5 | Q12: =O12*P12/10000000 -> 0.75012912 | R12: =O12*F12/10000000+IF(Assumptions!$C$6="Downside",Q12*Assumptions!$C$8,0) -> 0.53509211 | S12: =Q12*L12 -> 0.048758393 | T12: =O12*M12/10000000 -> 0.10001722 | U12: =Q12-SUM(R12:T12) -> 0.066261406 | V12: =IFERROR(U12/Q12,0) -> 0.088333333 | W12: =Assumptions!F64 -> Illustrative (replace with pilot) | X12: =Assumptions!C26&" | "&Assumptions!D26 -> Garam Masala | 5g trial
A13: =Assumptions!A65 -> FY22 | B13: =Assumptions!B65 -> GAR_T | C13: =Assumptions!B26 -> Spices | D13: =Assumptions!C65 -> Modern | E13: =Assumptions!E26*(1+Assumptions!$C$11)^0 -> 10 | F13: =Assumptions!F26*(1+Assumptions!$C$12)^0 -> 5.35 | G13: =Assumptions!G26 -> 52 | H13: =Assumptions!D65 -> 319 | I13: =Assumptions!E65 -> 8.88 | J13: =Assumptions!$C$13 -> 0.95 | K13: =Assumptions!B41 -> 0.28 | L13: =Assumptions!C41+IF(Assumptions!$C$6="Downside",Assumptions!$C$9,0) -> 0.14 | M13: =Assumptions!E41 -> 1.7 | N13: =H13*I13*G13*IF(Assumptions!$C$6="Downside",1-Assumptions!$C$7,1) -> 147301.44 | O13: =N13*J13 -> 139936.37 | P13: =E13*(1-K13) -> 7.2 | Q13: =O13*P13/10000000 -> 0.10075418 | R13: =O13*F13/10000000+IF(Assumptions!$C$6="Downside",Q13*Assumptions!$C$8,0) -> 0.074865957 | S13: =Q13*L13 -> 0.014105586 | T13: =O13*M13/10000000 -> 0.023789183 | U13: =Q13-SUM(R13:T13) -> -0.01200654 | V13: =IFERROR(U13/Q13,0) -> -0.11916667 | W13: =Assumptions!F65 -> Illustrative (replace with pilot) | X13: =Assumptions!C26&" | "&Assumptions!D26 -> Garam Masala | 5g trial
A14: =Assumptions!A66 -> FY22 | B14: =Assumptions!B66 -> GAR_T | C14: =Assumptions!B26 -> Spices | D14: =Assumptions!C66 -> QCom | E14: =Assumptions!E26*(1+Assumptions!$C$11)^0 -> 10 | F14: =Assumptions!F26*(1+Assumptions!$C$12)^0 -> 5.35 | G14: =Assumptions!G26 -> 52 | H14: =Assumptions!D66 -> 128 | I14: =Assumptions!E66 -> 26.64 | J14: =Assumptions!$C$13 -> 0.95 | K14: =Assumptions!B42 -> 0.38 | L14: =Assumptions!C42+IF(Assumptions!$C$6="Downside",Assumptions!$C$9,0) -> 0.24 | M14: =Assumptions!E42 -> 2 | N14: =H14*I14*G14*IF(Assumptions!$C$6="Downside",1-Assumptions!$C$7,1) -> 177315.84 | O14: =N14*J14 -> 168450.05 | P14: =E14*(1-K14) -> 6.2 | Q14: =O14*P14/10000000 -> 0.10443903 | R14: =O14*F14/10000000+IF(Assumptions!$C$6="Downside",Q14*Assumptions!$C$8,0) -> 0.090120776 | S14: =Q14*L14 -> 0.025065367 | T14: =O14*M14/10000000 -> 0.03369001 | U14: =Q14-SUM(R14:T14) -> -0.044437123 | V14: =IFERROR(U14/Q14,0) -> -0.42548387 | W14: =Assumptions!F66 -> Illustrative (replace with pilot) | X14: =Assumptions!C26&" | "&Assumptions!D26 -> Garam Masala | 5g trial
A15: =Assumptions!A67 -> FY22 | B15: =Assumptions!B67 -> GAR_L | C15: =Assumptions!B27 -> Spices | D15: =Assumptions!C67 -> GT | E15: =Assumptions!E27*(1+Assumptions!$C$11)^0 -> 49 | F15: =Assumptions!F27*(1+Assumptions!$C$12)^0 -> 23.5 | G15: =Assumptions!G27 -> 52 | H15: =Assumptions!D67 -> 11200 | I15: =Assumptions!E67 -> 2.64 | J15: =Assumptions!$C$13 -> 0.95 | K15: =Assumptions!B40 -> 0.25 | L15: =Assumptions!C40+IF(Assumptions!$C$6="Downside",Assumptions!$C$9,0) -> 0.065 | M15: =Assumptions!E40 -> 1 | N15: =H15*I15*G15*IF(Assumptions!$C$6="Downside",1-Assumptions!$C$7,1) -> 1537536 | O15: =N15*J15 -> 1460659.2 | P15: =E15*(1-K15) -> 36.75 | Q15: =O15*P15/10000000 -> 5.3679226 | R15: =O15*F15/10000000+IF(Assumptions!$C$6="Downside",Q15*Assumptions!$C$8,0) -> 3.4325491 | S15: =Q15*L15 -> 0.34891497 | T15: =O15*M15/10000000 -> 0.14606592 | U15: =Q15-SUM(R15:T15) -> 1.4403926 | V15: =IFERROR(U15/Q15,0) -> 0.26833333 | W15: =Assumptions!F67 -> Illustrative (replace with pilot) | X15: =Assumptions!C27&" | "&Assumptions!D27 -> Garam Masala | 50g pouch
A16: =Assumptions!A68 -> FY22 | B16: =Assumptions!B68 -> GAR_L | C16: =Assumptions!B27 -> Spices | D16: =Assumptions!C68 -> Modern | E16: =Assumptions!E27*(1+Assumptions!$C$11)^0 -> 49 | F16: =Assumptions!F27*(1+Assumptions!$C$12)^0 -> 23.5 | G16: =Assumptions!G27 -> 52 | H16: =Assumptions!D68 -> 392 | I16: =Assumptions!E68 -> 10.56 | J16: =Assumptions!$C$13 -> 0.95 | K16: =Assumptions!B41 -> 0.28 | L16: =Assumptions!C41+IF(Assumptions!$C$6="Downside",Assumptions!$C$9,0) -> 0.14 | M16: =Assumptions!E41 -> 1.7 | N16: =H16*I16*G16*IF(Assumptions!$C$6="Downside",1-Assumptions!$C$7,1) -> 215255.04 | O16: =N16*J16 -> 204492.29 | P16: =E16*(1-K16) -> 35.28 | Q16: =O16*P16/10000000 -> 0.72144879 | R16: =O16*F16/10000000+IF(Assumptions!$C$6="Downside",Q16*Assumptions!$C$8,0) -> 0.48055688 | S16: =Q16*L16 -> 0.10100283 | T16: =O16*M16/10000000 -> 0.034763689 | U16: =Q16-SUM(R16:T16) -> 0.1051254 | V16: =IFERROR(U16/Q16,0) -> 0.14571429 | W16: =Assumptions!F68 -> Illustrative (replace with pilot) | X16: =Assumptions!C27&" | "&Assumptions!D27 -> Garam Masala | 50g pouch
A17: =Assumptions!A69 -> FY22 | B17: =Assumptions!B69 -> GAR_L | C17: =Assumptions!B27 -> Spices | D17: =Assumptions!C69 -> QCom | E17: =Assumptions!E27*(1+Assumptions!$C$11)^0 -> 49 | F17: =Assumptions!F27*(1+Assumptions!$C$12)^0 -> 23.5 | G17: =Assumptions!G27 -> 52 | H17: =Assumptions!D69 -> 157 | I17: =Assumptions!E69 -> 31.68 | J17: =Assumptions!$C$13 -> 0.95 | K17: =Assumptions!B42 -> 0.38 | L17: =Assumptions!C42+IF(Assumptions!$C$6="Downside",Assumptions!$C$9,0) -> 0.24 | M17: =Assumptions!E42 -> 2 | N17: =H17*I17*G17*IF(Assumptions!$C$6="Downside",1-Assumptions!$C$7,1) -> 258635.52 | O17: =N17*J17 -> 245703.74 | P17: =E17*(1-K17) -> 30.38 | Q17: =O17*P17/10000000 -> 0.74644797 | R17: =O17*F17/10000000+IF(Assumptions!$C$6="Downside",Q17*Assumptions!$C$8,0) -> 0.5774038 | S17: =Q17*L17 -> 0.17914751 | T17: =O17*M17/10000000 -> 0.049140749 | U17: =Q17-SUM(R17:T17) -> -0.059244087 | V17: =IFERROR(U17/Q17,0) -> -0.079368005 | W17: =Assumptions!F69 -> Illustrative (replace with pilot) | X17: =Assumptions!C27&" | "&Assumptions!D27 -> Garam Masala | 50g pouch
A18: =Assumptions!A70 -> FY22 | B18: =Assumptions!B70 -> GIN_T | C18: =Assumptions!B28 -> Premixes | D18: =Assumptions!C70 -> GT | E18: =Assumptions!E28*(1+Assumptions!$C$11)^0 -> 10 | F18: =Assumptions!F28*(1+Assumptions!$C$12)^0 -> 4.35 | G18: =Assumptions!G28 -> 26 | H18: =Assumptions!D70 -> 8320 | I18: =Assumptions!E70 -> 3.12 | J18: =Assumptions!$C$13 -> 0.95 | K18: =Assumptions!B40 -> 0.25 | L18: =Assumptions!C40+IF(Assumptions!$C$6="Downside",Assumptions!$C$9,0) -> 0.065 | M18: =Assumptions!E40 -> 1 | N18: =H18*I18*G18*IF(Assumptions!$C$6="Downside",1-Assumptions!$C$7,1) -> 674918.4 | O18: =N18*J18 -> 641172.48 | P18: =E18*(1-K18) -> 7.5 | Q18: =O18*P18/10000000 -> 0.48087936 | R18: =O18*F18/10000000+IF(Assumptions!$C$6="Downside",Q18*Assumptions!$C$8,0) -> 0.27891003 | S18: =Q18*L18 -> 0.031257158 | T18: =O18*M18/10000000 -> 0.064117248 | U18: =Q18-SUM(R18:T18) -> 0.10659492 | V18: =IFERROR(U18/Q18,0) -> 0.22166667 | W18: =Assumptions!F70 -> Illustrative (replace with pilot) | X18: =Assumptions!C28&" | "&Assumptions!D28 -> Ginger-Lemon Hot Drink | 15g single sachet
A19: =Assumptions!A71 -> FY22 | B19: =Assumptions!B71 -> GIN_T | C19: =Assumptions!B28 -> Premixes | D19: =Assumptions!C71 -> Modern | E19: =Assumptions!E28*(1+Assumptions!$C$11)^0 -> 10 | F19: =Assumptions!F28*(1+Assumptions!$C$12)^0 -> 4.35 | G19: =Assumptions!G28 -> 26 | H19: =Assumptions!D71 -> 291 | I19: =Assumptions!E71 -> 12.48 | J19: =Assumptions!$C$13 -> 0.95 | K19: =Assumptions!B41 -> 0.28 | L19: =Assumptions!C41+IF(Assumptions!$C$6="Downside",Assumptions!$C$9,0) -> 0.14 | M19: =Assumptions!E41 -> 1.7 | N19: =H19*I19*G19*IF(Assumptions!$C$6="Downside",1-Assumptions!$C$7,1) -> 94423.68 | O19: =N19*J19 -> 89702.496 | P19: =E19*(1-K19) -> 7.2 | Q19: =O19*P19/10000000 -> 0.064585797 | R19: =O19*F19/10000000+IF(Assumptions!$C$6="Downside",Q19*Assumptions!$C$8,0) -> 0.039020586 | S19: =Q19*L19 -> 0.0090420116 | T19: =O19*M19/10000000 -> 0.015249424 | U19: =Q19-SUM(R19:T19) -> 0.0012737754 | V19: =IFERROR(U19/Q19,0) -> 0.019722222 | W19: =Assumptions!F71 -> Illustrative (replace with pilot) | X19: =Assumptions!C28&" | "&Assumptions!D28 -> Ginger-Lemon Hot Drink | 15g single sachet
A20: =Assumptions!A72 -> FY22 | B20: =Assumptions!B72 -> GIN_T | C20: =Assumptions!B28 -> Premixes | D20: =Assumptions!C72 -> QCom | E20: =Assumptions!E28*(1+Assumptions!$C$11)^0 -> 10 | F20: =Assumptions!F28*(1+Assumptions!$C$12)^0 -> 4.35 | G20: =Assumptions!G28 -> 26 | H20: =Assumptions!D72 -> 116 | I20: =Assumptions!E72 -> 37.44 | J20: =Assumptions!$C$13 -> 0.95 | K20: =Assumptions!B42 -> 0.38 | L20: =Assumptions!C42+IF(Assumptions!$C$6="Downside",Assumptions!$C$9,0) -> 0.24 | M20: =Assumptions!E42 -> 2 | N20: =H20*I20*G20*IF(Assumptions!$C$6="Downside",1-Assumptions!$C$7,1) -> 112919.04 | O20: =N20*J20 -> 107273.09 | P20: =E20*(1-K20) -> 6.2 | Q20: =O20*P20/10000000 -> 0.066509315 | R20: =O20*F20/10000000+IF(Assumptions!$C$6="Downside",Q20*Assumptions!$C$8,0) -> 0.046663793 | S20: =Q20*L20 -> 0.015962235 | T20: =O20*M20/10000000 -> 0.021454618 | U20: =Q20-SUM(R20:T20) -> -0.017571332 | V20: =IFERROR(U20/Q20,0) -> -0.26419355 | W20: =Assumptions!F72 -> Illustrative (replace with pilot) | X20: =Assumptions!C28&" | "&Assumptions!D28 -> Ginger-Lemon Hot Drink | 15g single sachet
A21: =Assumptions!A73 -> FY22 | B21: =Assumptions!B73 -> GIN_L | C21: =Assumptions!B29 -> Premixes | D21: =Assumptions!C73 -> GT | E21: =Assumptions!E29*(1+Assumptions!$C$11)^0 -> 99 | F21: =Assumptions!F29*(1+Assumptions!$C$12)^0 -> 44 | G21: =Assumptions!G29 -> 26 | H21: =Assumptions!D73 -> 6240 | I21: =Assumptions!E73 -> 2.52 | J21: =Assumptions!$C$13 -> 0.95 | K21: =Assumptions!B40 -> 0.25 | L21: =Assumptions!C40+IF(Assumptions!$C$6="Downside",Assumptions!$C$9,0) -> 0.065 | M21: =Assumptions!E40 -> 1 | N21: =H21*I21*G21*IF(Assumptions!$C$6="Downside",1-Assumptions!$C$7,1) -> 408844.8 | O21: =N21*J21 -> 388402.56 | P21: =E21*(1-K21) -> 74.25 | Q21: =O21*P21/10000000 -> 2.883889 | R21: =O21*F21/10000000+IF(Assumptions!$C$6="Downside",Q21*Assumptions!$C$8,0) -> 1.7089713 | S21: =Q21*L21 -> 0.18745279 | T21: =O21*M21/10000000 -> 0.038840256 | U21: =Q21-SUM(R21:T21) -> 0.9486247 | V21: =IFERROR(U21/Q21,0) -> 0.32893939 | W21: =Assumptions!F73 -> Illustrative (replace with pilot) | X21: =Assumptions!C29&" | "&Assumptions!D29 -> Ginger-Lemon Hot Drink | 10-sachet pack
A22: =Assumptions!A74 -> FY22 | B22: =Assumptions!B74 -> GIN_L | C22: =Assumptions!B29 -> Premixes | D22: =Assumptions!C74 -> Modern | E22: =Assumptions!E29*(1+Assumptions!$C$11)^0 -> 99 | F22: =Assumptions!F29*(1+Assumptions!$C$12)^0 -> 44 | G22: =Assumptions!G29 -> 26 | H22: =Assumptions!D74 -> 218 | I22: =Assumptions!E74 -> 10.08 | J22: =Assumptions!$C$13 -> 0.95 | K22: =Assumptions!B41 -> 0.28 | L22: =Assumptions!C41+IF(Assumptions!$C$6="Downside",Assumptions!$C$9,0) -> 0.14 | M22: =Assumptions!E41 -> 1.7 | N22: =H22*I22*G22*IF(Assumptions!$C$6="Downside",1-Assumptions!$C$7,1) -> 57133.44 | O22: =N22*J22 -> 54276.768 | P22: =E22*(1-K22) -> 71.28 | Q22: =O22*P22/10000000 -> 0.3868848 | R22: =O22*F22/10000000+IF(Assumptions!$C$6="Downside",Q22*Assumptions!$C$8,0) -> 0.23881778 | S22: =Q22*L22 -> 0.054163872 | T22: =O22*M22/10000000 -> 0.0092270506 | U22: =Q22-SUM(R22:T22) -> 0.0846761 | V22: =IFERROR(U22/Q22,0) -> 0.21886644 | W22: =Assumptions!F74 -> Illustrative (replace with pilot) | X22: =Assumptions!C29&" | "&Assumptions!D29 -> Ginger-Lemon Hot Drink | 10-sachet pack
A23: =Assumptions!A75 -> FY22 | B23: =Assumptions!B75 -> GIN_L | C23: =Assumptions!B29 -> Premixes | D23: =Assumptions!C75 -> QCom | E23: =Assumptions!E29*(1+Assumptions!$C$11)^0 -> 99 | F23: =Assumptions!F29*(1+Assumptions!$C$12)^0 -> 44 | G23: =Assumptions!G29 -> 26 | H23: =Assumptions!D75 -> 87 | I23: =Assumptions!E75 -> 30.24 | J23: =Assumptions!$C$13 -> 0.95 | K23: =Assumptions!B42 -> 0.38 | L23: =Assumptions!C42+IF(Assumptions!$C$6="Downside",Assumptions!$C$9,0) -> 0.24 | M23: =Assumptions!E42 -> 2 | N23: =H23*I23*G23*IF(Assumptions!$C$6="Downside",1-Assumptions!$C$7,1) -> 68402.88 | O23: =N23*J23 -> 64982.736 | P23: =E23*(1-K23) -> 61.38 | Q23: =O23*P23/10000000 -> 0.39886403 | R23: =O23*F23/10000000+IF(Assumptions!$C$6="Downside",Q23*Assumptions!$C$8,0) -> 0.28592404 | S23: =Q23*L23 -> 0.095727368 | T23: =O23*M23/10000000 -> 0.012996547 | U23: =Q23-SUM(R23:T23) -> 0.0042160799 | V23: =IFERROR(U23/Q23,0) -> 0.010570218 | W23: =Assumptions!F75 -> Illustrative (replace with pilot) | X23: =Assumptions!C29&" | "&Assumptions!D29 -> Ginger-Lemon Hot Drink | 10-sachet pack
A24: =Assumptions!A76 -> FY22 | B24: =Assumptions!B76 -> BAD_T | C24: =Assumptions!B30 -> Premixes | D24: =Assumptions!C76 -> GT | E24: =Assumptions!E30*(1+Assumptions!$C$11)^0 -> 10 | F24: =Assumptions!F30*(1+Assumptions!$C$12)^0 -> 4.5 | G24: =Assumptions!G30 -> 26 | H24: =Assumptions!D76 -> 6720 | I24: =Assumptions!E76 -> 2.16 | J24: =Assumptions!$C$13 -> 0.95 | K24: =Assumptions!B40 -> 0.25 | L24: =Assumptions!C40+IF(Assumptions!$C$6="Downside",Assumptions!$C$9,0) -> 0.065 | M24: =Assumptions!E40 -> 1 | N24: =H24*I24*G24*IF(Assumptions!$C$6="Downside",1-Assumptions!$C$7,1) -> 377395.2 | O24: =N24*J24 -> 358525.44 | P24: =E24*(1-K24) -> 7.5 | Q24: =O24*P24/10000000 -> 0.26889408 | R24: =O24*F24/10000000+IF(Assumptions!$C$6="Downside",Q24*Assumptions!$C$8,0) -> 0.16133645 | S24: =Q24*L24 -> 0.017478115 | T24: =O24*M24/10000000 -> 0.035852544 | U24: =Q24-SUM(R24:T24) -> 0.054226973 | V24: =IFERROR(U24/Q24,0) -> 0.20166667 | W24: =Assumptions!F76 -> Illustrative (replace with pilot) | X24: =Assumptions!C30&" | "&Assumptions!D30 -> Badam-Elaichi Milk Mix | 15g single sachet
A25: =Assumptions!A77 -> FY22 | B25: =Assumptions!B77 -> BAD_T | C25: =Assumptions!B30 -> Premixes | D25: =Assumptions!C77 -> Modern | E25: =Assumptions!E30*(1+Assumptions!$C$11)^0 -> 10 | F25: =Assumptions!F30*(1+Assumptions!$C$12)^0 -> 4.5 | G25: =Assumptions!G30 -> 26 | H25: =Assumptions!D77 -> 235 | I25: =Assumptions!E77 -> 8.64 | J25: =Assumptions!$C$13 -> 0.95 | K25: =Assumptions!B41 -> 0.28 | L25: =Assumptions!C41+IF(Assumptions!$C$6="Downside",Assumptions!$C$9,0) -> 0.14 | M25: =Assumptions!E41 -> 1.7 | N25: =H25*I25*G25*IF(Assumptions!$C$6="Downside",1-Assumptions!$C$7,1) -> 52790.4 | O25: =N25*J25 -> 50150.88 | P25: =E25*(1-K25) -> 7.2 | Q25: =O25*P25/10000000 -> 0.036108634 | R25: =O25*F25/10000000+IF(Assumptions!$C$6="Downside",Q25*Assumptions!$C$8,0) -> 0.022567896 | S25: =Q25*L25 -> 0.0050552087 | T25: =O25*M25/10000000 -> 0.0085256496 | U25: =Q25-SUM(R25:T25) -> -4.0120704e-05 | V25: =IFERROR(U25/Q25,0) -> -0.0011111111 | W25: =Assumptions!F77 -> Illustrative (replace with pilot) | X25: =Assumptions!C30&" | "&Assumptions!D30 -> Badam-Elaichi Milk Mix | 15g single sachet
A26: =Assumptions!A78 -> FY22 | B26: =Assumptions!B78 -> BAD_T | C26: =Assumptions!B30 -> Premixes | D26: =Assumptions!C78 -> QCom | E26: =Assumptions!E30*(1+Assumptions!$C$11)^0 -> 10 | F26: =Assumptions!F30*(1+Assumptions!$C$12)^0 -> 4.5 | G26: =Assumptions!G30 -> 26 | H26: =Assumptions!D78 -> 94 | I26: =Assumptions!E78 -> 25.92 | J26: =Assumptions!$C$13 -> 0.95 | K26: =Assumptions!B42 -> 0.38 | L26: =Assumptions!C42+IF(Assumptions!$C$6="Downside",Assumptions!$C$9,0) -> 0.24 | M26: =Assumptions!E42 -> 2 | N26: =H26*I26*G26*IF(Assumptions!$C$6="Downside",1-Assumptions!$C$7,1) -> 63348.48 | O26: =N26*J26 -> 60181.056 | P26: =E26*(1-K26) -> 6.2 | Q26: =O26*P26/10000000 -> 0.037312255 | R26: =O26*F26/10000000+IF(Assumptions!$C$6="Downside",Q26*Assumptions!$C$8,0) -> 0.027081475 | S26: =Q26*L26 -> 0.0089549411 | T26: =O26*M26/10000000 -> 0.012036211 | U26: =Q26-SUM(R26:T26) -> -0.010760373 | V26: =IFERROR(U26/Q26,0) -> -0.2883871 | W26: =Assumptions!F78 -> Illustrative (replace with pilot) | X26: =Assumptions!C30&" | "&Assumptions!D30 -> Badam-Elaichi Milk Mix | 15g single sachet
A27: =Assumptions!A79 -> FY22 | B27: =Assumptions!B79 -> BAD_L | C27: =Assumptions!B31 -> Premixes | D27: =Assumptions!C79 -> GT | E27: =Assumptions!E31*(1+Assumptions!$C$11)^0 -> 99 | F27: =Assumptions!F31*(1+Assumptions!$C$12)^0 -> 45.5 | G27: =Assumptions!G31 -> 26 | H27: =Assumptions!D79 -> 5440 | I27: =Assumptions!E79 -> 1.98 | J27: =Assumptions!$C$13 -> 0.95 | K27: =Assumptions!B40 -> 0.25 | L27: =Assumptions!C40+IF(Assumptions!$C$6="Downside",Assumptions!$C$9,0) -> 0.065 | M27: =Assumptions!E40 -> 1 | N27: =H27*I27*G27*IF(Assumptions!$C$6="Downside",1-Assumptions!$C$7,1) -> 280051.2 | O27: =N27*J27 -> 266048.64 | P27: =E27*(1-K27) -> 74.25 | Q27: =O27*P27/10000000 -> 1.9754112 | R27: =O27*F27/10000000+IF(Assumptions!$C$6="Downside",Q27*Assumptions!$C$8,0) -> 1.2105213 | S27: =Q27*L27 -> 0.12840172 | T27: =O27*M27/10000000 -> 0.026604864 | U27: =Q27-SUM(R27:T27) -> 0.60988325 | V27: =IFERROR(U27/Q27,0) -> 0.30873737 | W27: =Assumptions!F79 -> Illustrative (replace with pilot) | X27: =Assumptions!C31&" | "&Assumptions!D31 -> Badam-Elaichi Milk Mix | 150g pouch
A28: =Assumptions!A80 -> FY22 | B28: =Assumptions!B80 -> BAD_L | C28: =Assumptions!B31 -> Premixes | D28: =Assumptions!C80 -> Modern | E28: =Assumptions!E31*(1+Assumptions!$C$11)^0 -> 99 | F28: =Assumptions!F31*(1+Assumptions!$C$12)^0 -> 45.5 | G28: =Assumptions!G31 -> 26 | H28: =Assumptions!D80 -> 190 | I28: =Assumptions!E80 -> 7.92 | J28: =Assumptions!$C$13 -> 0.95 | K28: =Assumptions!B41 -> 0.28 | L28: =Assumptions!C41+IF(Assumptions!$C$6="Downside",Assumptions!$C$9,0) -> 0.14 | M28: =Assumptions!E41 -> 1.7 | N28: =H28*I28*G28*IF(Assumptions!$C$6="Downside",1-Assumptions!$C$7,1) -> 39124.8 | O28: =N28*J28 -> 37168.56 | P28: =E28*(1-K28) -> 71.28 | Q28: =O28*P28/10000000 -> 0.2649375 | R28: =O28*F28/10000000+IF(Assumptions!$C$6="Downside",Q28*Assumptions!$C$8,0) -> 0.16911695 | S28: =Q28*L28 -> 0.037091249 | T28: =O28*M28/10000000 -> 0.0063186552 | U28: =Q28-SUM(R28:T28) -> 0.052410643 | V28: =IFERROR(U28/Q28,0) -> 0.19782267 | W28: =Assumptions!F80 -> Illustrative (replace with pilot) | X28: =Assumptions!C31&" | "&Assumptions!D31 -> Badam-Elaichi Milk Mix | 150g pouch
A29: =Assumptions!A81 -> FY22 | B29: =Assumptions!B81 -> BAD_L | C29: =Assumptions!B31 -> Premixes | D29: =Assumptions!C81 -> QCom | E29: =Assumptions!E31*(1+Assumptions!$C$11)^0 -> 99 | F29: =Assumptions!F31*(1+Assumptions!$C$12)^0 -> 45.5 | G29: =Assumptions!G31 -> 26 | H29: =Assumptions!D81 -> 76 | I29: =Assumptions!E81 -> 23.76 | J29: =Assumptions!$C$13 -> 0.95 | K29: =Assumptions!B42 -> 0.38 | L29: =Assumptions!C42+IF(Assumptions!$C$6="Downside",Assumptions!$C$9,0) -> 0.24 | M29: =Assumptions!E42 -> 2 | N29: =H29*I29*G29*IF(Assumptions!$C$6="Downside",1-Assumptions!$C$7,1) -> 46949.76 | O29: =N29*J29 -> 44602.272 | P29: =E29*(1-K29) -> 61.38 | Q29: =O29*P29/10000000 -> 0.27376875 | R29: =O29*F29/10000000+IF(Assumptions!$C$6="Downside",Q29*Assumptions!$C$8,0) -> 0.20294034 | S29: =Q29*L29 -> 0.065704499 | T29: =O29*M29/10000000 -> 0.0089204544 | U29: =Q29-SUM(R29:T29) -> -0.0037965454 | V29: =IFERROR(U29/Q29,0) -> -0.013867709 | W29: =Assumptions!F81 -> Illustrative (replace with pilot) | X29: =Assumptions!C31&" | "&Assumptions!D31 -> Badam-Elaichi Milk Mix | 150g pouch
A30: =Assumptions!A82 -> FY22 | B30: =Assumptions!B82 -> CHU_T | C30: =Assumptions!B32 -> Condiments | D30: =Assumptions!C82 -> GT | E30: =Assumptions!E32*(1+Assumptions!$C$11)^0 -> 10 | F30: =Assumptions!F32*(1+Assumptions!$C$12)^0 -> 4.8 | G30: =Assumptions!G32 -> 52 | H30: =Assumptions!D82 -> 6880 | I30: =Assumptions!E82 -> 1.74 | J30: =Assumptions!$C$13 -> 0.95 | K30: =Assumptions!B40 -> 0.25 | L30: =Assumptions!C40+IF(Assumptions!$C$6="Downside",Assumptions!$C$9,0) -> 0.065 | M30: =Assumptions!E40 -> 1 | N30: =H30*I30*G30*IF(Assumptions!$C$6="Downside",1-Assumptions!$C$7,1) -> 622502.4 | O30: =N30*J30 -> 591377.28 | P30: =E30*(1-K30) -> 7.5 | Q30: =O30*P30/10000000 -> 0.44353296 | R30: =O30*F30/10000000+IF(Assumptions!$C$6="Downside",Q30*Assumptions!$C$8,0) -> 0.28386109 | S30: =Q30*L30 -> 0.028829642 | T30: =O30*M30/10000000 -> 0.059137728 | U30: =Q30-SUM(R30:T30) -> 0.071704495 | V30: =IFERROR(U30/Q30,0) -> 0.16166667 | W30: =Assumptions!F82 -> Illustrative (replace with pilot) | X30: =Assumptions!C32&" | "&Assumptions!D32 -> Tamarind-Date Chutney | 20g sachet
A31: =Assumptions!A83 -> FY22 | B31: =Assumptions!B83 -> CHU_T | C31: =Assumptions!B32 -> Condiments | D31: =Assumptions!C83 -> Modern | E31: =Assumptions!E32*(1+Assumptions!$C$11)^0 -> 10 | F31: =Assumptions!F32*(1+Assumptions!$C$12)^0 -> 4.8 | G31: =Assumptions!G32 -> 52 | H31: =Assumptions!D83 -> 241 | I31: =Assumptions!E83 -> 6.96 | J31: =Assumptions!$C$13 -> 0.95 | K31: =Assumptions!B41 -> 0.28 | L31: =Assumptions!C41+IF(Assumptions!$C$6="Downside",Assumptions!$C$9,0) -> 0.14 | M31: =Assumptions!E41 -> 1.7 | N31: =H31*I31*G31*IF(Assumptions!$C$6="Downside",1-Assumptions!$C$7,1) -> 87222.72 | O31: =N31*J31 -> 82861.584 | P31: =E31*(1-K31) -> 7.2 | Q31: =O31*P31/10000000 -> 0.05966034 | R31: =O31*F31/10000000+IF(Assumptions!$C$6="Downside",Q31*Assumptions!$C$8,0) -> 0.03977356 | S31: =Q31*L31 -> 0.0083524477 | T31: =O31*M31/10000000 -> 0.014086469 | U31: =Q31-SUM(R31:T31) -> -0.0025521368 | V31: =IFERROR(U31/Q31,0) -> -0.042777778 | W31: =Assumptions!F83 -> Illustrative (replace with pilot) | X31: =Assumptions!C32&" | "&Assumptions!D32 -> Tamarind-Date Chutney | 20g sachet
A32: =Assumptions!A84 -> FY22 | B32: =Assumptions!B84 -> CHU_T | C32: =Assumptions!B32 -> Condiments | D32: =Assumptions!C84 -> QCom | E32: =Assumptions!E32*(1+Assumptions!$C$11)^0 -> 10 | F32: =Assumptions!F32*(1+Assumptions!$C$12)^0 -> 4.8 | G32: =Assumptions!G32 -> 52 | H32: =Assumptions!D84 -> 96 | I32: =Assumptions!E84 -> 20.88 | J32: =Assumptions!$C$13 -> 0.95 | K32: =Assumptions!B42 -> 0.38 | L32: =Assumptions!C42+IF(Assumptions!$C$6="Downside",Assumptions!$C$9,0) -> 0.24 | M32: =Assumptions!E42 -> 2 | N32: =H32*I32*G32*IF(Assumptions!$C$6="Downside",1-Assumptions!$C$7,1) -> 104232.96 | O32: =N32*J32 -> 99021.312 | P32: =E32*(1-K32) -> 6.2 | Q32: =O32*P32/10000000 -> 0.061393213 | R32: =O32*F32/10000000+IF(Assumptions!$C$6="Downside",Q32*Assumptions!$C$8,0) -> 0.04753023 | S32: =Q32*L32 -> 0.014734371 | T32: =O32*M32/10000000 -> 0.019804262 | U32: =Q32-SUM(R32:T32) -> -0.02067565 | V32: =IFERROR(U32/Q32,0) -> -0.33677419 | W32: =Assumptions!F84 -> Illustrative (replace with pilot) | X32: =Assumptions!C32&" | "&Assumptions!D32 -> Tamarind-Date Chutney | 20g sachet
A33: =Assumptions!A85 -> FY22 | B33: =Assumptions!B85 -> CHU_L | C33: =Assumptions!B33 -> Condiments | D33: =Assumptions!C85 -> GT | E33: =Assumptions!E33*(1+Assumptions!$C$11)^0 -> 99 | F33: =Assumptions!F33*(1+Assumptions!$C$12)^0 -> 47 | G33: =Assumptions!G33 -> 52 | H33: =Assumptions!D85 -> 5280 | I33: =Assumptions!E85 -> 1.32 | J33: =Assumptions!$C$13 -> 0.95 | K33: =Assumptions!B40 -> 0.25 | L33: =Assumptions!C40+IF(Assumptions!$C$6="Downside",Assumptions!$C$9,0) -> 0.065 | M33: =Assumptions!E40 -> 1 | N33: =H33*I33*G33*IF(Assumptions!$C$6="Downside",1-Assumptions!$C$7,1) -> 362419.2 | O33: =N33*J33 -> 344298.24 | P33: =E33*(1-K33) -> 74.25 | Q33: =O33*P33/10000000 -> 2.5564144 | R33: =O33*F33/10000000+IF(Assumptions!$C$6="Downside",Q33*Assumptions!$C$8,0) -> 1.6182017 | S33: =Q33*L33 -> 0.16616694 | T33: =O33*M33/10000000 -> 0.034429824 | U33: =Q33-SUM(R33:T33) -> 0.73761594 | V33: =IFERROR(U33/Q33,0) -> 0.28853535 | W33: =Assumptions!F85 -> Illustrative (replace with pilot) | X33: =Assumptions!C33&" | "&Assumptions!D33 -> Tamarind-Date Chutney | 200g pack
A34: =Assumptions!A86 -> FY22 | B34: =Assumptions!B86 -> CHU_L | C34: =Assumptions!B33 -> Condiments | D34: =Assumptions!C86 -> Modern | E34: =Assumptions!E33*(1+Assumptions!$C$11)^0 -> 99 | F34: =Assumptions!F33*(1+Assumptions!$C$12)^0 -> 47 | G34: =Assumptions!G33 -> 52 | H34: =Assumptions!D86 -> 185 | I34: =Assumptions!E86 -> 5.28 | J34: =Assumptions!$C$13 -> 0.95 | K34: =Assumptions!B41 -> 0.28 | L34: =Assumptions!C41+IF(Assumptions!$C$6="Downside",Assumptions!$C$9,0) -> 0.14 | M34: =Assumptions!E41 -> 1.7 | N34: =H34*I34*G34*IF(Assumptions!$C$6="Downside",1-Assumptions!$C$7,1) -> 50793.6 | O34: =N34*J34 -> 48253.92 | P34: =E34*(1-K34) -> 71.28 | Q34: =O34*P34/10000000 -> 0.34395394 | R34: =O34*F34/10000000+IF(Assumptions!$C$6="Downside",Q34*Assumptions!$C$8,0) -> 0.22679342 | S34: =Q34*L34 -> 0.048153552 | T34: =O34*M34/10000000 -> 0.0082031664 | U34: =Q34-SUM(R34:T34) -> 0.0608038 | V34: =IFERROR(U34/Q34,0) -> 0.1767789 | W34: =Assumptions!F86 -> Illustrative (replace with pilot) | X34: =Assumptions!C33&" | "&Assumptions!D33 -> Tamarind-Date Chutney | 200g pack
A35: =Assumptions!A87 -> FY22 | B35: =Assumptions!B87 -> CHU_L | C35: =Assumptions!B33 -> Condiments | D35: =Assumptions!C87 -> QCom | E35: =Assumptions!E33*(1+Assumptions!$C$11)^0 -> 99 | F35: =Assumptions!F33*(1+Assumptions!$C$12)^0 -> 47 | G35: =Assumptions!G33 -> 52 | H35: =Assumptions!D87 -> 74 | I35: =Assumptions!E87 -> 15.84 | J35: =Assumptions!$C$13 -> 0.95 | K35: =Assumptions!B42 -> 0.38 | L35: =Assumptions!C42+IF(Assumptions!$C$6="Downside",Assumptions!$C$9,0) -> 0.24 | M35: =Assumptions!E42 -> 2 | N35: =H35*I35*G35*IF(Assumptions!$C$6="Downside",1-Assumptions!$C$7,1) -> 60952.32 | O35: =N35*J35 -> 57904.704 | P35: =E35*(1-K35) -> 61.38 | Q35: =O35*P35/10000000 -> 0.35541907 | R35: =O35*F35/10000000+IF(Assumptions!$C$6="Downside",Q35*Assumptions!$C$8,0) -> 0.27215211 | S35: =Q35*L35 -> 0.085300578 | T35: =O35*M35/10000000 -> 0.011580941 | U35: =Q35-SUM(R35:T35) -> -0.013614554 | V35: =IFERROR(U35/Q35,0) -> -0.038305637 | W35: =Assumptions!F87 -> Illustrative (replace with pilot) | X35: =Assumptions!C33&" | "&Assumptions!D33 -> Tamarind-Date Chutney | 200g pack
A36: =Assumptions!A88 -> FY22 | B36: =Assumptions!B88 -> PIC_T | C36: =Assumptions!B34 -> Condiments | D36: =Assumptions!C88 -> GT | E36: =Assumptions!E34*(1+Assumptions!$C$11)^0 -> 10 | F36: =Assumptions!F34*(1+Assumptions!$C$12)^0 -> 4.7 | G36: =Assumptions!G34 -> 52 | H36: =Assumptions!D88 -> 6720 | I36: =Assumptions!E88 -> 1.62 | J36: =Assumptions!$C$13 -> 0.95 | K36: =Assumptions!B40 -> 0.25 | L36: =Assumptions!C40+IF(Assumptions!$C$6="Downside",Assumptions!$C$9,0) -> 0.065 | M36: =Assumptions!E40 -> 1 | N36: =H36*I36*G36*IF(Assumptions!$C$6="Downside",1-Assumptions!$C$7,1) -> 566092.8 | O36: =N36*J36 -> 537788.16 | P36: =E36*(1-K36) -> 7.5 | Q36: =O36*P36/10000000 -> 0.40334112 | R36: =O36*F36/10000000+IF(Assumptions!$C$6="Downside",Q36*Assumptions!$C$8,0) -> 0.25276044 | S36: =Q36*L36 -> 0.026217173 | T36: =O36*M36/10000000 -> 0.053778816 | U36: =Q36-SUM(R36:T36) -> 0.070584696 | V36: =IFERROR(U36/Q36,0) -> 0.175 | W36: =Assumptions!F88 -> Illustrative (replace with pilot) | X36: =Assumptions!C34&" | "&Assumptions!D34 -> Lime Pickle | 20g sachet
A37: =Assumptions!A89 -> FY22 | B37: =Assumptions!B89 -> PIC_T | C37: =Assumptions!B34 -> Condiments | D37: =Assumptions!C89 -> Modern | E37: =Assumptions!E34*(1+Assumptions!$C$11)^0 -> 10 | F37: =Assumptions!F34*(1+Assumptions!$C$12)^0 -> 4.7 | G37: =Assumptions!G34 -> 52 | H37: =Assumptions!D89 -> 235 | I37: =Assumptions!E89 -> 6.48 | J37: =Assumptions!$C$13 -> 0.95 | K37: =Assumptions!B41 -> 0.28 | L37: =Assumptions!C41+IF(Assumptions!$C$6="Downside",Assumptions!$C$9,0) -> 0.14 | M37: =Assumptions!E41 -> 1.7 | N37: =H37*I37*G37*IF(Assumptions!$C$6="Downside",1-Assumptions!$C$7,1) -> 79185.6 | O37: =N37*J37 -> 75226.32 | P37: =E37*(1-K37) -> 7.2 | Q37: =O37*P37/10000000 -> 0.05416295 | R37: =O37*F37/10000000+IF(Assumptions!$C$6="Downside",Q37*Assumptions!$C$8,0) -> 0.03535637 | S37: =Q37*L37 -> 0.0075828131 | T37: =O37*M37/10000000 -> 0.012788474 | U37: =Q37-SUM(R37:T37) -> -0.0015647075 | V37: =IFERROR(U37/Q37,0) -> -0.028888889 | W37: =Assumptions!F89 -> Illustrative (replace with pilot) | X37: =Assumptions!C34&" | "&Assumptions!D34 -> Lime Pickle | 20g sachet
A38: =Assumptions!A90 -> FY22 | B38: =Assumptions!B90 -> PIC_T | C38: =Assumptions!B34 -> Condiments | D38: =Assumptions!C90 -> QCom | E38: =Assumptions!E34*(1+Assumptions!$C$11)^0 -> 10 | F38: =Assumptions!F34*(1+Assumptions!$C$12)^0 -> 4.7 | G38: =Assumptions!G34 -> 52 | H38: =Assumptions!D90 -> 94 | I38: =Assumptions!E90 -> 19.44 | J38: =Assumptions!$C$13 -> 0.95 | K38: =Assumptions!B42 -> 0.38 | L38: =Assumptions!C42+IF(Assumptions!$C$6="Downside",Assumptions!$C$9,0) -> 0.24 | M38: =Assumptions!E42 -> 2 | N38: =H38*I38*G38*IF(Assumptions!$C$6="Downside",1-Assumptions!$C$7,1) -> 95022.72 | O38: =N38*J38 -> 90271.584 | P38: =E38*(1-K38) -> 6.2 | Q38: =O38*P38/10000000 -> 0.055968382 | R38: =O38*F38/10000000+IF(Assumptions!$C$6="Downside",Q38*Assumptions!$C$8,0) -> 0.042427644 | S38: =Q38*L38 -> 0.013432412 | T38: =O38*M38/10000000 -> 0.018054317 | U38: =Q38-SUM(R38:T38) -> -0.017945991 | V38: =IFERROR(U38/Q38,0) -> -0.32064516 | W38: =Assumptions!F90 -> Illustrative (replace with pilot) | X38: =Assumptions!C34&" | "&Assumptions!D34 -> Lime Pickle | 20g sachet
A39: =Assumptions!A91 -> FY22 | B39: =Assumptions!B91 -> PIC_L | C39: =Assumptions!B35 -> Condiments | D39: =Assumptions!C91 -> GT | E39: =Assumptions!E35*(1+Assumptions!$C$11)^0 -> 99 | F39: =Assumptions!F35*(1+Assumptions!$C$12)^0 -> 46.5 | G39: =Assumptions!G35 -> 52 | H39: =Assumptions!D91 -> 5920 | I39: =Assumptions!E91 -> 1.32 | J39: =Assumptions!$C$13 -> 0.95 | K39: =Assumptions!B40 -> 0.25 | L39: =Assumptions!C40+IF(Assumptions!$C$6="Downside",Assumptions!$C$9,0) -> 0.065 | M39: =Assumptions!E40 -> 1 | N39: =H39*I39*G39*IF(Assumptions!$C$6="Downside",1-Assumptions!$C$7,1) -> 406348.8 | O39: =N39*J39 -> 386031.36 | P39: =E39*(1-K39) -> 74.25 | Q39: =O39*P39/10000000 -> 2.8662828 | R39: =O39*F39/10000000+IF(Assumptions!$C$6="Downside",Q39*Assumptions!$C$8,0) -> 1.7950458 | S39: =Q39*L39 -> 0.18630839 | T39: =O39*M39/10000000 -> 0.038603136 | U39: =Q39-SUM(R39:T39) -> 0.8463255 | V39: =IFERROR(U39/Q39,0) -> 0.29526936 | W39: =Assumptions!F91 -> Illustrative (replace with pilot) | X39: =Assumptions!C35&" | "&Assumptions!D35 -> Lime Pickle | 200g pack
A40: =Assumptions!A92 -> FY22 | B40: =Assumptions!B92 -> PIC_L | C40: =Assumptions!B35 -> Condiments | D40: =Assumptions!C92 -> Modern | E40: =Assumptions!E35*(1+Assumptions!$C$11)^0 -> 99 | F40: =Assumptions!F35*(1+Assumptions!$C$12)^0 -> 46.5 | G40: =Assumptions!G35 -> 52 | H40: =Assumptions!D92 -> 207 | I40: =Assumptions!E92 -> 5.28 | J40: =Assumptions!$C$13 -> 0.95 | K40: =Assumptions!B41 -> 0.28 | L40: =Assumptions!C41+IF(Assumptions!$C$6="Downside",Assumptions!$C$9,0) -> 0.14 | M40: =Assumptions!E41 -> 1.7 | N40: =H40*I40*G40*IF(Assumptions!$C$6="Downside",1-Assumptions!$C$7,1) -> 56833.92 | O40: =N40*J40 -> 53992.224 | P40: =E40*(1-K40) -> 71.28 | Q40: =O40*P40/10000000 -> 0.38485657 | R40: =O40*F40/10000000+IF(Assumptions!$C$6="Downside",Q40*Assumptions!$C$8,0) -> 0.25106384 | S40: =Q40*L40 -> 0.05387992 | T40: =O40*M40/10000000 -> 0.0091786781 | U40: =Q40-SUM(R40:T40) -> 0.070734133 | V40: =IFERROR(U40/Q40,0) -> 0.18379349 | W40: =Assumptions!F92 -> Illustrative (replace with pilot) | X40: =Assumptions!C35&" | "&Assumptions!D35 -> Lime Pickle | 200g pack
A41: =Assumptions!A93 -> FY22 | B41: =Assumptions!B93 -> PIC_L | C41: =Assumptions!B35 -> Condiments | D41: =Assumptions!C93 -> QCom | E41: =Assumptions!E35*(1+Assumptions!$C$11)^0 -> 99 | F41: =Assumptions!F35*(1+Assumptions!$C$12)^0 -> 46.5 | G41: =Assumptions!G35 -> 52 | H41: =Assumptions!D93 -> 83 | I41: =Assumptions!E93 -> 15.84 | J41: =Assumptions!$C$13 -> 0.95 | K41: =Assumptions!B42 -> 0.38 | L41: =Assumptions!C42+IF(Assumptions!$C$6="Downside",Assumptions!$C$9,0) -> 0.24 | M41: =Assumptions!E42 -> 2 | N41: =H41*I41*G41*IF(Assumptions!$C$6="Downside",1-Assumptions!$C$7,1) -> 68365.44 | O41: =N41*J41 -> 64947.168 | P41: =E41*(1-K41) -> 61.38 | Q41: =O41*P41/10000000 -> 0.39864572 | R41: =O41*F41/10000000+IF(Assumptions!$C$6="Downside",Q41*Assumptions!$C$8,0) -> 0.30200433 | S41: =Q41*L41 -> 0.095674972 | T41: =O41*M41/10000000 -> 0.012989434 | U41: =Q41-SUM(R41:T41) -> -0.01202302 | V41: =IFERROR(U41/Q41,0) -> -0.030159661 | W41: =Assumptions!F93 -> Illustrative (replace with pilot) | X41: =Assumptions!C35&" | "&Assumptions!D35 -> Lime Pickle | 200g pack
A42: =Assumptions!A94 -> FY23 | B42: =Assumptions!B94 -> SAB_T | C42: =Assumptions!B24 -> Spices | D42: =Assumptions!C94 -> GT | E42: =Assumptions!E24*(1+Assumptions!$C$11)^1 -> 10 | F42: =Assumptions!F24*(1+Assumptions!$C$12)^1 -> 5.25 | G42: =Assumptions!G24 -> 52 | H42: =Assumptions!D94 -> 36400 | I42: =Assumptions!E94 -> 3.78 | J42: =Assumptions!$C$13 -> 0.95 | K42: =Assumptions!B40 -> 0.25 | L42: =Assumptions!C40+IF(Assumptions!$C$6="Downside",Assumptions!$C$9,0) -> 0.065 | M42: =Assumptions!E40 -> 1 | N42: =H42*I42*G42*IF(Assumptions!$C$6="Downside",1-Assumptions!$C$7,1) -> 7154784 | O42: =N42*J42 -> 6797044.8 | P42: =E42*(1-K42) -> 7.5 | Q42: =O42*P42/10000000 -> 5.0977836 | R42: =O42*F42/10000000+IF(Assumptions!$C$6="Downside",Q42*Assumptions!$C$8,0) -> 3.5684485 | S42: =Q42*L42 -> 0.33135593 | T42: =O42*M42/10000000 -> 0.67970448 | U42: =Q42-SUM(R42:T42) -> 0.51827467 | V42: =IFERROR(U42/Q42,0) -> 0.10166667 | W42: =Assumptions!F94 -> Illustrative (replace with pilot) | X42: =Assumptions!C24&" | "&Assumptions!D24 -> Everyday Sabzi Masala | 8g trial
...

Sheet Portfolio
A1: PORTFOLIO | company revenue bridge & FY24 targets
A5: Revenue bridge (₹Cr) | B5: FY21 actual | C5: FY22 | D5: FY23 | E5: FY24
A6: Legacy portfolio | B6: =Assumptions!F6 -> 560 | C6: =Assumptions!B17 -> 580 | D6: =Assumptions!C17 -> 605 | E6: =Assumptions!D17 -> 630
A7: Spices — new | C7: =SUMIFS(SKU_Channel_Model!$Q$6:$Q$113,SKU_Channel_Model!$A$6:$A$113,"FY22",SKU_Channel_Model!$C$6:$C$113,"Spices") -> 17.711862 | D7: =SUMIFS(SKU_Channel_Model!$Q$6:$Q$113,SKU_Channel_Model!$A$6:$A$113,"FY23",SKU_Channel_Model!$C$6:$C$113,"Spices") -> 90.929627 | E7: =SUMIFS(SKU_Channel_Model!$Q$6:$Q$113,SKU_Channel_Model!$A$6:$A$113,"FY24",SKU_Channel_Model!$C$6:$C$113,"Spices") -> 184.48265
A8: Winter premixes — new | C8: =SUMIFS(SKU_Channel_Model!$Q$6:$Q$113,SKU_Channel_Model!$A$6:$A$113,"FY22",SKU_Channel_Model!$C$6:$C$113,"Premixes") -> 7.1380447 | D8: =SUMIFS(SKU_Channel_Model!$Q$6:$Q$113,SKU_Channel_Model!$A$6:$A$113,"FY23",SKU_Channel_Model!$C$6:$C$113,"Premixes") -> 36.668846 | E8: =SUMIFS(SKU_Channel_Model!$Q$6:$Q$113,SKU_Channel_Model!$A$6:$A$113,"FY24",SKU_Channel_Model!$C$6:$C$113,"Premixes") -> 74.395013
A9: Condiments — new | C9: =SUMIFS(SKU_Channel_Model!$Q$6:$Q$113,SKU_Channel_Model!$A$6:$A$113,"FY22",SKU_Channel_Model!$C$6:$C$113,"Condiments") -> 7.9836316 | D9: =SUMIFS(SKU_Channel_Model!$Q$6:$Q$113,SKU_Channel_Model!$A$6:$A$113,"FY23",SKU_Channel_Model!$C$6:$C$113,"Condiments") -> 41.036876 | E9: =SUMIFS(SKU_Channel_Model!$Q$6:$Q$113,SKU_Channel_Model!$A$6:$A$113,"FY24",SKU_Channel_Model!$C$6:$C$113,"Condiments") -> 83.155415
A10: NEW product sales | B10: =Assumptions!F6*Assumptions!F7 -> 23.52 | C10: =SUM(C7:C9) -> 32.833539 | D10: =SUM(D7:D9) -> 168.63535 | E10: =SUM(E7:E9) -> 342.03308
